2025-01-17 18:20:44,524 - WARNING - No refresh token provided.
2025-01-17 18:20:44,526 - WARNING - Unauthorized: /accounts/test/
2025-01-17 18:20:53,572 - DEBUG - Starting new HTTPS connection (1): api.intra.42.fr:443
2025-01-17 18:20:54,063 - DEBUG - https://api.intra.42.fr:443 "POST /oauth/token HTTP/1.1" 200 None
2025-01-17 18:20:54,065 - DEBUG - Starting new HTTPS connection (1): api.intra.42.fr:443
2025-01-17 18:20:54,899 - DEBUG - https://api.intra.42.fr:443 "GET /v2/me HTTP/1.1" 200 None
2025-01-17 18:24:51,627 - INFO - User bbosnak authenticated successfully.
2025-01-17 18:30:54,098 - WARNING - No refresh token provided.
2025-01-17 18:30:54,099 - WARNING - Unauthorized: /accounts/test/
2025-01-17 18:30:55,019 - DEBUG - Starting new HTTPS connection (1): api.intra.42.fr:443
2025-01-17 18:30:55,572 - DEBUG - https://api.intra.42.fr:443 "POST /oauth/token HTTP/1.1" 200 None
2025-01-17 18:30:55,651 - DEBUG - Starting new HTTPS connection (1): api.intra.42.fr:443
2025-01-17 18:30:56,438 - DEBUG - https://api.intra.42.fr:443 "GET /v2/me HTTP/1.1" 200 None
2025-01-17 18:34:01,110 - DEBUG - Starting new HTTPS connection (1): api.intra.42.fr:443
2025-01-17 18:34:01,561 - DEBUG - https://api.intra.42.fr:443 "POST /oauth/token HTTP/1.1" 200 None
2025-01-17 18:34:01,563 - DEBUG - Starting new HTTPS connection (1): api.intra.42.fr:443
2025-01-17 18:34:02,215 - DEBUG - https://api.intra.42.fr:443 "GET /v2/me HTTP/1.1" 200 None
2025-01-17 18:42:39,568 - WARNING - No refresh token provided.
2025-01-17 18:42:39,570 - WARNING - Unauthorized: /accounts/test/
2025-01-17 18:42:40,084 - DEBUG - Starting new HTTPS connection (1): api.intra.42.fr:443
2025-01-17 18:42:40,554 - DEBUG - https://api.intra.42.fr:443 "POST /oauth/token HTTP/1.1" 200 None
2025-01-17 18:42:40,556 - DEBUG - Starting new HTTPS connection (1): api.intra.42.fr:443
2025-01-17 18:42:41,230 - DEBUG - https://api.intra.42.fr:443 "GET /v2/me HTTP/1.1" 200 None
2025-01-17 18:44:00,425 - DEBUG - Starting new HTTPS connection (1): api.intra.42.fr:443
2025-01-17 18:44:00,804 - DEBUG - https://api.intra.42.fr:443 "POST /oauth/token HTTP/1.1" 200 None
2025-01-17 18:44:00,883 - DEBUG - Starting new HTTPS connection (1): api.intra.42.fr:443
2025-01-17 18:44:01,531 - DEBUG - https://api.intra.42.fr:443 "GET /v2/me HTTP/1.1" 200 None
2025-01-17 19:00:25,427 - WARNING - No refresh token provided.
2025-01-17 19:00:25,430 - WARNING - Unauthorized: /accounts/test/
2025-01-17 19:00:25,915 - DEBUG - Starting new HTTPS connection (1): api.intra.42.fr:443
2025-01-17 19:00:26,339 - DEBUG - https://api.intra.42.fr:443 "POST /oauth/token HTTP/1.1" 200 None
2025-01-17 19:00:26,417 - DEBUG - Starting new HTTPS connection (1): api.intra.42.fr:443
2025-01-17 19:00:27,134 - DEBUG - https://api.intra.42.fr:443 "GET /v2/me HTTP/1.1" 200 None
2025-01-17 19:02:11,228 - DEBUG - Starting new HTTPS connection (1): api.intra.42.fr:443
2025-01-17 19:02:11,612 - DEBUG - https://api.intra.42.fr:443 "POST /oauth/token HTTP/1.1" 200 None
2025-01-17 19:02:11,691 - DEBUG - Starting new HTTPS connection (1): api.intra.42.fr:443
2025-01-17 19:02:12,256 - DEBUG - https://api.intra.42.fr:443 "GET /v2/me HTTP/1.1" 200 None
2025-01-17 19:03:55,237 - WARNING - No refresh token provided.
2025-01-17 19:03:55,238 - WARNING - Unauthorized: /accounts/test/
2025-01-17 19:03:55,412 - DEBUG - Starting new HTTPS connection (1): api.intra.42.fr:443
2025-01-17 19:03:55,778 - DEBUG - https://api.intra.42.fr:443 "POST /oauth/token HTTP/1.1" 200 None
2025-01-17 19:03:55,860 - DEBUG - Starting new HTTPS connection (1): api.intra.42.fr:443
2025-01-17 19:03:56,497 - DEBUG - https://api.intra.42.fr:443 "GET /v2/me HTTP/1.1" 200 None
2025-01-17 19:05:13,930 - DEBUG - Starting new HTTPS connection (1): api.intra.42.fr:443
2025-01-17 19:05:14,341 - DEBUG - https://api.intra.42.fr:443 "POST /oauth/token HTTP/1.1" 200 None
2025-01-17 19:05:14,419 - DEBUG - Starting new HTTPS connection (1): api.intra.42.fr:443
2025-01-17 19:05:15,069 - DEBUG - https://api.intra.42.fr:443 "GET /v2/me HTTP/1.1" 200 None
2025-01-17 19:14:26,246 - WARNING - No refresh token provided.
2025-01-17 19:14:26,249 - WARNING - Unauthorized: /accounts/test/
2025-01-17 19:14:26,727 - DEBUG - Starting new HTTPS connection (1): api.intra.42.fr:443
2025-01-17 19:14:27,196 - DEBUG - https://api.intra.42.fr:443 "POST /oauth/token HTTP/1.1" 200 None
2025-01-17 19:14:27,199 - DEBUG - Starting new HTTPS connection (1): api.intra.42.fr:443
2025-01-17 19:14:27,926 - DEBUG - https://api.intra.42.fr:443 "GET /v2/me HTTP/1.1" 200 None
2025-01-17 19:17:44,587 - DEBUG - Starting new HTTPS connection (1): api.intra.42.fr:443
2025-01-17 19:17:44,959 - DEBUG - https://api.intra.42.fr:443 "POST /oauth/token HTTP/1.1" 200 None
2025-01-17 19:17:44,961 - DEBUG - Starting new HTTPS connection (1): api.intra.42.fr:443
2025-01-17 19:17:45,617 - DEBUG - https://api.intra.42.fr:443 "GET /v2/me HTTP/1.1" 200 None
2025-01-17 19:19:09,957 - WARNING - No refresh token provided.
2025-01-17 19:19:09,958 - WARNING - Unauthorized: /accounts/test/
2025-01-17 19:19:10,127 - DEBUG - Starting new HTTPS connection (1): api.intra.42.fr:443
2025-01-17 19:19:10,508 - DEBUG - https://api.intra.42.fr:443 "POST /oauth/token HTTP/1.1" 200 None
2025-01-17 19:19:10,510 - DEBUG - Starting new HTTPS connection (1): api.intra.42.fr:443
2025-01-17 19:19:11,095 - DEBUG - https://api.intra.42.fr:443 "GET /v2/me HTTP/1.1" 200 None
2025-01-17 19:19:27,336 - WARNING - Bad Request: /accounts/verify-2fa/
2025-01-17 19:20:46,595 - WARNING - No refresh token provided.
2025-01-17 19:20:46,596 - WARNING - Unauthorized: /accounts/test/
2025-01-17 19:20:46,781 - DEBUG - Starting new HTTPS connection (1): api.intra.42.fr:443
2025-01-17 19:20:47,230 - DEBUG - https://api.intra.42.fr:443 "POST /oauth/token HTTP/1.1" 200 None
2025-01-17 19:20:47,313 - DEBUG - Starting new HTTPS connection (1): api.intra.42.fr:443
2025-01-17 19:20:47,951 - DEBUG - https://api.intra.42.fr:443 "GET /v2/me HTTP/1.1" 200 None
2025-01-17 19:26:13,977 - WARNING - No refresh token provided.
2025-01-17 19:26:13,978 - WARNING - Unauthorized: /accounts/test/
2025-01-17 19:26:14,193 - DEBUG - Starting new HTTPS connection (1): api.intra.42.fr:443
2025-01-17 19:26:14,565 - DEBUG - https://api.intra.42.fr:443 "POST /oauth/token HTTP/1.1" 200 None
2025-01-17 19:26:14,644 - DEBUG - Starting new HTTPS connection (1): api.intra.42.fr:443
2025-01-17 19:26:15,297 - DEBUG - https://api.intra.42.fr:443 "GET /v2/me HTTP/1.1" 200 None
2025-01-17 19:32:49,175 - WARNING - No refresh token provided.
2025-01-17 19:32:49,177 - WARNING - Unauthorized: /accounts/test/
2025-01-17 19:32:49,407 - DEBUG - Starting new HTTPS connection (1): api.intra.42.fr:443
2025-01-17 19:32:49,817 - DEBUG - https://api.intra.42.fr:443 "POST /oauth/token HTTP/1.1" 200 None
2025-01-17 19:32:49,902 - DEBUG - Starting new HTTPS connection (1): api.intra.42.fr:443
2025-01-17 19:32:50,541 - DEBUG - https://api.intra.42.fr:443 "GET /v2/me HTTP/1.1" 200 None
2025-01-17 19:40:46,404 - WARNING - No refresh token provided.
2025-01-17 19:40:46,405 - WARNING - Unauthorized: /accounts/test/
2025-01-17 19:40:46,928 - DEBUG - Starting new HTTPS connection (1): api.intra.42.fr:443
2025-01-17 19:40:47,342 - DEBUG - https://api.intra.42.fr:443 "POST /oauth/token HTTP/1.1" 200 None
2025-01-17 19:40:47,344 - DEBUG - Starting new HTTPS connection (1): api.intra.42.fr:443
2025-01-17 19:40:48,006 - DEBUG - https://api.intra.42.fr:443 "GET /v2/me HTTP/1.1" 200 None
2025-01-17 19:41:31,094 - WARNING - No refresh token provided.
2025-01-17 19:41:31,095 - WARNING - Unauthorized: /accounts/test/
2025-01-17 19:41:31,284 - DEBUG - Starting new HTTPS connection (1): api.intra.42.fr:443
2025-01-17 19:41:31,652 - DEBUG - https://api.intra.42.fr:443 "POST /oauth/token HTTP/1.1" 200 None
2025-01-17 19:41:31,729 - DEBUG - Starting new HTTPS connection (1): api.intra.42.fr:443
2025-01-17 19:41:32,388 - DEBUG - https://api.intra.42.fr:443 "GET /v2/me HTTP/1.1" 200 None
2025-01-17 19:43:12,148 - WARNING - No refresh token provided.
2025-01-17 19:43:12,149 - WARNING - Unauthorized: /accounts/test/
2025-01-17 19:43:12,353 - DEBUG - Starting new HTTPS connection (1): api.intra.42.fr:443
2025-01-17 19:43:12,721 - DEBUG - https://api.intra.42.fr:443 "POST /oauth/token HTTP/1.1" 200 None
2025-01-17 19:43:12,726 - DEBUG - Starting new HTTPS connection (1): api.intra.42.fr:443
2025-01-17 19:43:13,356 - DEBUG - https://api.intra.42.fr:443 "GET /v2/me HTTP/1.1" 200 None
2025-01-17 19:43:52,885 - WARNING - No refresh token provided.
2025-01-17 19:43:52,885 - WARNING - Unauthorized: /accounts/test/
2025-01-17 19:43:53,064 - DEBUG - Starting new HTTPS connection (1): api.intra.42.fr:443
2025-01-17 19:43:53,453 - DEBUG - https://api.intra.42.fr:443 "POST /oauth/token HTTP/1.1" 200 None
2025-01-17 19:43:53,534 - DEBUG - Starting new HTTPS connection (1): api.intra.42.fr:443
2025-01-17 19:43:54,179 - DEBUG - https://api.intra.42.fr:443 "GET /v2/me HTTP/1.1" 200 None
2025-01-17 19:44:38,132 - WARNING - No refresh token provided.
2025-01-17 19:44:38,133 - WARNING - Unauthorized: /accounts/test/
2025-01-17 19:44:38,340 - DEBUG - Starting new HTTPS connection (1): api.intra.42.fr:443
2025-01-17 19:44:38,735 - DEBUG - https://api.intra.42.fr:443 "POST /oauth/token HTTP/1.1" 200 None
2025-01-17 19:44:38,812 - DEBUG - Starting new HTTPS connection (1): api.intra.42.fr:443
2025-01-17 19:44:39,441 - DEBUG - https://api.intra.42.fr:443 "GET /v2/me HTTP/1.1" 200 None
2025-01-17 19:45:11,632 - WARNING - No refresh token provided.
2025-01-17 19:45:11,634 - WARNING - Unauthorized: /accounts/test/
2025-01-17 19:45:11,827 - DEBUG - Starting new HTTPS connection (1): api.intra.42.fr:443
2025-01-17 19:45:12,280 - DEBUG - https://api.intra.42.fr:443 "POST /oauth/token HTTP/1.1" 200 None
2025-01-17 19:45:12,282 - DEBUG - Starting new HTTPS connection (1): api.intra.42.fr:443
2025-01-17 19:45:12,980 - DEBUG - https://api.intra.42.fr:443 "GET /v2/me HTTP/1.1" 200 None
2025-01-18 16:47:42,814 - WARNING - No refresh token provided.
2025-01-18 16:47:42,815 - WARNING - Unauthorized: /accounts/test/
2025-01-18 16:47:43,156 - DEBUG - Starting new HTTPS connection (1): api.intra.42.fr:443
2025-01-18 16:47:43,426 - DEBUG - https://api.intra.42.fr:443 "POST /oauth/token HTTP/1.1" 200 None
2025-01-18 16:47:43,428 - DEBUG - Starting new HTTPS connection (1): api.intra.42.fr:443
2025-01-18 16:47:43,830 - DEBUG - https://api.intra.42.fr:443 "GET /v2/me HTTP/1.1" 200 None
2025-01-18 16:48:24,747 - INFO - User edamar authenticated successfully.
2025-01-18 16:48:53,529 - WARNING - Forbidden: /accounts/logout/
2025-01-18 16:48:53,471 - WARNING - Forbidden: /accounts/logout/
2025-01-18 16:48:58,512 - INFO - User edamar authenticated successfully.
2025-01-18 16:48:58,568 - WARNING - Not Found: /accounts/get_profile/
2025-01-18 16:49:16,175 - WARNING - No refresh token provided.
2025-01-18 16:49:16,176 - WARNING - Unauthorized: /accounts/test/
2025-01-18 16:49:16,449 - DEBUG - Starting new HTTPS connection (1): api.intra.42.fr:443
2025-01-18 16:49:16,698 - DEBUG - https://api.intra.42.fr:443 "POST /oauth/token HTTP/1.1" 200 None
2025-01-18 16:49:16,700 - DEBUG - Starting new HTTPS connection (1): api.intra.42.fr:443
2025-01-18 16:49:17,331 - DEBUG - https://api.intra.42.fr:443 "GET /v2/me HTTP/1.1" 200 None
2025-01-18 16:49:42,731 - WARNING - No refresh token provided.
2025-01-18 16:49:42,731 - WARNING - Unauthorized: /accounts/test/
2025-01-18 16:49:42,927 - DEBUG - Starting new HTTPS connection (1): api.intra.42.fr:443
2025-01-18 16:49:43,071 - DEBUG - https://api.intra.42.fr:443 "POST /oauth/token HTTP/1.1" 200 None
2025-01-18 16:49:43,073 - DEBUG - Starting new HTTPS connection (1): api.intra.42.fr:443
2025-01-18 16:49:43,627 - DEBUG - https://api.intra.42.fr:443 "GET /v2/me HTTP/1.1" 200 None
2025-01-18 16:49:55,891 - WARNING - Forbidden: /accounts/verify-2fa/
2025-01-18 16:52:18,883 - INFO - /app/accounts/views.py changed, reloading.
2025-01-18 16:52:32,402 - INFO - /app/accounts/views.py changed, reloading.
2025-01-18 16:52:47,291 - INFO - /app/accounts/views.py changed, reloading.
2025-01-18 16:52:48,926 - INFO - /app/accounts/views.py changed, reloading.
2025-01-18 16:53:18,762 - INFO - /app/accounts/views.py changed, reloading.
2025-01-18 16:53:41,593 - INFO - /app/accounts/urls.py changed, reloading.
2025-01-18 16:53:47,227 - INFO - /app/accounts/urls.py changed, reloading.
2025-01-18 16:53:48,856 - INFO - /app/accounts/urls.py changed, reloading.
2025-01-18 16:53:51,500 - INFO - /app/accounts/urls.py changed, reloading.
2025-01-18 16:56:23,741 - INFO - /app/accounts/urls.py changed, reloading.
2025-01-18 16:56:28,467 - INFO - /app/accounts/urls.py changed, reloading.
2025-01-18 16:56:35,161 - INFO - /app/accounts/urls.py changed, reloading.
2025-01-18 16:56:37,480 - INFO - /app/accounts/urls.py changed, reloading.
2025-01-18 16:56:48,346 - INFO - /app/accounts/views.py changed, reloading.
2025-01-18 16:57:54,520 - INFO - /app/accounts/views.py changed, reloading.
2025-01-18 16:58:18,780 - INFO - /app/accounts/views.py changed, reloading.
2025-01-18 16:58:24,967 - WARNING - No refresh token provided.
2025-01-18 16:58:24,968 - WARNING - Unauthorized: /accounts/test/
2025-01-18 16:58:25,321 - DEBUG - Starting new HTTPS connection (1): api.intra.42.fr:443
2025-01-18 16:58:25,598 - DEBUG - https://api.intra.42.fr:443 "POST /oauth/token HTTP/1.1" 200 None
2025-01-18 16:58:25,599 - DEBUG - Starting new HTTPS connection (1): api.intra.42.fr:443
2025-01-18 16:58:26,062 - DEBUG - https://api.intra.42.fr:443 "GET /v2/me HTTP/1.1" 200 None
2025-01-18 16:58:42,570 - WARNING - Not Found: /accounts/get_profile/
2025-01-18 16:58:53,941 - WARNING - Forbidden: /accounts/logout/
2025-01-18 16:58:59,003 - INFO - /app/accounts/views.py changed, reloading.
2025-01-18 16:59:00,407 - INFO - User edamar authenticated successfully.
2025-01-18 16:59:00,459 - WARNING - Not Found: /accounts/get_profile/
2025-01-18 16:59:01,298 - WARNING - Unauthorized: /accounts/logout/
2025-01-18 16:59:40,260 - INFO - /app/accounts/views.py changed, reloading.
2025-01-18 16:59:42,720 - INFO - User edamar authenticated successfully.
2025-01-18 16:59:42,770 - WARNING - Not Found: /accounts/get_profile/
2025-01-18 16:59:43,645 - WARNING - Unauthorized: /accounts/logout/
2025-01-18 16:59:49,037 - INFO - /app/accounts/views.py changed, reloading.
2025-01-18 16:59:52,699 - INFO - /app/accounts/views.py changed, reloading.
2025-01-18 17:12:27,719 - INFO - /app/accounts/views.py changed, reloading.
2025-01-18 17:13:09,740 - INFO - /app/accounts/views.py changed, reloading.
2025-01-18 17:13:15,424 - INFO - User edamar authenticated successfully.
2025-01-18 17:13:15,557 - WARNING - Not Found: /accounts/get_profile/
2025-01-18 17:13:16,753 - WARNING - Forbidden: /accounts/logout/
2025-01-18 17:13:39,269 - WARNING - No refresh token provided.
2025-01-18 17:13:39,270 - WARNING - Unauthorized: /accounts/test/
2025-01-18 17:13:39,600 - DEBUG - Starting new HTTPS connection (1): api.intra.42.fr:443
2025-01-18 17:13:39,873 - DEBUG - https://api.intra.42.fr:443 "POST /oauth/token HTTP/1.1" 200 None
2025-01-18 17:13:39,876 - DEBUG - Starting new HTTPS connection (1): api.intra.42.fr:443
2025-01-18 17:13:40,392 - DEBUG - https://api.intra.42.fr:443 "GET /v2/me HTTP/1.1" 200 None
2025-01-18 17:14:00,370 - WARNING - Forbidden: /accounts/verify-2fa/
2025-01-18 17:14:16,709 - INFO - /app/accounts/views.py changed, reloading.
2025-01-18 17:14:30,878 - INFO - /app/accounts/views.py changed, reloading.
2025-01-18 17:14:49,244 - INFO - /app/accounts/views.py changed, reloading.
2025-01-18 17:15:01,222 - INFO - /app/accounts/views.py changed, reloading.
2025-01-18 17:15:08,010 - INFO - /app/accounts/views.py changed, reloading.
2025-01-18 17:15:09,541 - WARNING - Not Found: /accounts/get_profile/
2025-01-18 17:15:25,907 - INFO - /app/accounts/views.py changed, reloading.
2025-01-18 17:15:44,456 - INFO - /app/accounts/views.py changed, reloading.
2025-01-18 17:15:46,106 - INFO - User edamar authenticated successfully.
2025-01-18 17:15:46,147 - WARNING - Unauthorized: /accounts/get_profile/
2025-01-18 17:15:46,153 - INFO - /app/accounts/views.py changed, reloading.
2025-01-18 17:15:50,125 - INFO - /app/accounts/views.py changed, reloading.
2025-01-18 17:15:51,815 - INFO - /app/accounts/views.py changed, reloading.
2025-01-18 17:15:53,618 - INFO - User edamar authenticated successfully.
2025-01-18 17:15:53,659 - WARNING - Unauthorized: /accounts/get_profile/
2025-01-18 17:17:18,780 - INFO - /app/accounts/views.py changed, reloading.
2025-01-18 17:17:25,671 - INFO - /app/accounts/views.py changed, reloading.
2025-01-18 17:17:29,540 - INFO - /app/accounts/views.py changed, reloading.
2025-01-18 17:21:42,118 - INFO - /app/accounts/views.py changed, reloading.
2025-01-18 17:21:45,949 - INFO - User edamar authenticated successfully.
2025-01-18 17:21:46,072 - WARNING - Not Found: /accounts/get_profile/
2025-01-18 17:21:51,574 - WARNING - Forbidden: /accounts/logout/
2025-01-18 17:21:59,138 - INFO - /app/accounts/views.py changed, reloading.
2025-01-18 17:29:11,294 - INFO - /app/pong_game/settings.py changed, reloading.
2025-01-18 17:33:43,830 - INFO - /app/accounts/views.py changed, reloading.
2025-01-18 17:33:45,573 - INFO - /app/accounts/views.py changed, reloading.
2025-01-18 17:37:57,797 - INFO - /app/accounts/views.py changed, reloading.
2025-01-18 17:38:03,501 - INFO - /app/accounts/views.py changed, reloading.
2025-01-18 17:38:05,180 - INFO - /app/accounts/views.py changed, reloading.
2025-01-18 17:38:06,889 - INFO - /app/accounts/views.py changed, reloading.
2025-01-18 17:38:10,660 - INFO - /app/accounts/views.py changed, reloading.
2025-01-18 17:38:15,398 - INFO - /app/accounts/views.py changed, reloading.
2025-01-18 17:38:18,165 - INFO - /app/accounts/views.py changed, reloading.
2025-01-18 17:38:21,843 - INFO - /app/accounts/views.py changed, reloading.
2025-01-18 17:38:24,401 - INFO - /app/accounts/views.py changed, reloading.
2025-01-18 17:41:17,605 - WARNING - No refresh token provided.
2025-01-18 17:41:17,606 - WARNING - Unauthorized: /accounts/test/
2025-01-18 17:41:17,902 - DEBUG - Starting new HTTPS connection (1): api.intra.42.fr:443
2025-01-18 17:41:18,179 - DEBUG - https://api.intra.42.fr:443 "POST /oauth/token HTTP/1.1" 200 None
2025-01-18 17:41:18,181 - DEBUG - Starting new HTTPS connection (1): api.intra.42.fr:443
2025-01-18 17:41:18,703 - DEBUG - https://api.intra.42.fr:443 "GET /v2/me HTTP/1.1" 200 None
2025-01-18 17:41:41,651 - INFO - User edamar authenticated successfully.
2025-01-18 17:41:44,819 - INFO - User edamar authenticated successfully.
2025-01-18 17:41:49,520 - INFO - User edamar authenticated successfully.
2025-01-18 17:42:33,398 - INFO - User edamar authenticated successfully.
2025-01-18 17:42:37,440 - INFO - {'detail': errordetail(string='given token not valid for any token type', code='token_not_valid'), 'code': errordetail(string='token_not_valid', code='token_not_valid'), 'messages': [{'token_class': errordetail(string='accesstoken', code='token_not_valid'), 'token_type': errordetail(string='access', code='token_not_valid'), 'message': errordetail(string='token is invalid or expired', code='token_not_valid')}]}
2025-01-18 17:43:01,723 - INFO - /app/accounts/views.py changed, reloading.
2025-01-18 17:43:04,566 - INFO - /app/accounts/views.py changed, reloading.
2025-01-18 17:43:06,067 - INFO - /app/accounts/views.py changed, reloading.
2025-01-18 17:43:07,812 - INFO - /app/accounts/views.py changed, reloading.
2025-01-18 17:43:29,510 - WARNING - No refresh token provided.
2025-01-18 17:43:29,510 - WARNING - Unauthorized: /accounts/test/
2025-01-18 17:43:29,792 - DEBUG - Starting new HTTPS connection (1): api.intra.42.fr:443
2025-01-18 17:43:30,043 - DEBUG - https://api.intra.42.fr:443 "POST /oauth/token HTTP/1.1" 200 None
2025-01-18 17:43:30,045 - DEBUG - Starting new HTTPS connection (1): api.intra.42.fr:443
2025-01-18 17:43:30,467 - DEBUG - https://api.intra.42.fr:443 "GET /v2/me HTTP/1.1" 200 None
2025-01-18 17:43:44,420 - WARNING - Not Found: /accounts/get_profile/
2025-01-18 17:45:35,090 - INFO - {'detail': errordetail(string='given token not valid for any token type', code='token_not_valid'), 'code': errordetail(string='token_not_valid', code='token_not_valid'), 'messages': [{'token_class': errordetail(string='accesstoken', code='token_not_valid'), 'token_type': errordetail(string='access', code='token_not_valid'), 'message': errordetail(string='token is invalid or expired', code='token_not_valid')}]}
2025-01-18 17:45:35,148 - WARNING - Not Found: /accounts/get_profile/
2025-01-18 18:03:21,038 - INFO - {'detail': errordetail(string='given token not valid for any token type', code='token_not_valid'), 'code': errordetail(string='token_not_valid', code='token_not_valid'), 'messages': [{'token_class': errordetail(string='accesstoken', code='token_not_valid'), 'token_type': errordetail(string='access', code='token_not_valid'), 'message': errordetail(string='token is invalid or expired', code='token_not_valid')}]}
2025-01-18 18:03:21,183 - WARNING - Not Found: /accounts/get_profile/
2025-01-18 18:03:22,284 - WARNING - Forbidden: /accounts/logout/
2025-01-18 18:03:22,566 - WARNING - Forbidden: /accounts/logout/
2025-01-18 18:03:30,882 - WARNING - No refresh token provided.
2025-01-18 18:03:30,883 - WARNING - Unauthorized: /accounts/test/
2025-01-18 18:03:31,232 - DEBUG - Starting new HTTPS connection (1): api.intra.42.fr:443
2025-01-18 18:03:31,503 - DEBUG - https://api.intra.42.fr:443 "POST /oauth/token HTTP/1.1" 200 None
2025-01-18 18:03:31,504 - DEBUG - Starting new HTTPS connection (1): api.intra.42.fr:443
2025-01-18 18:03:32,025 - DEBUG - https://api.intra.42.fr:443 "GET /v2/me HTTP/1.1" 200 None
2025-01-18 18:03:51,194 - INFO - User edamar authenticated successfully.
2025-01-18 18:28:43,954 - WARNING - No refresh token provided.
2025-01-18 18:28:43,955 - WARNING - Unauthorized: /accounts/test/
2025-01-18 18:28:44,260 - DEBUG - Starting new HTTPS connection (1): api.intra.42.fr:443
2025-01-18 18:28:44,445 - DEBUG - https://api.intra.42.fr:443 "POST /oauth/token HTTP/1.1" 200 None
2025-01-18 18:28:44,446 - DEBUG - Starting new HTTPS connection (1): api.intra.42.fr:443
2025-01-18 18:28:44,907 - DEBUG - https://api.intra.42.fr:443 "GET /v2/me HTTP/1.1" 200 None
2025-01-18 18:28:45,987 - ERROR - Internal Server Error: /accounts/callback/
Traceback (most recent call last):
  File "/usr/local/lib/python3.13/site-packages/django/core/handlers/exception.py", line 55, in inner
    response = get_response(request)
  File "/usr/local/lib/python3.13/site-packages/django/core/handlers/base.py", line 197, in _get_response
    response = wrapped_callback(request, *callback_args, **callback_kwargs)
  File "/usr/local/lib/python3.13/site-packages/django/views/decorators/csrf.py", line 65, in _view_wrapper
    return view_func(request, *args, **kwargs)
  File "/usr/local/lib/python3.13/site-packages/django/views/generic/base.py", line 104, in view
    return self.dispatch(request, *args, **kwargs)
           ~~~~~~~~~~~~~^^^^^^^^^^^^^^^^^^^^^^^^^^
  File "/usr/local/lib/python3.13/site-packages/rest_framework/views.py", line 509, in dispatch
    response = self.handle_exception(exc)
  File "/usr/local/lib/python3.13/site-packages/rest_framework/views.py", line 469, in handle_exception
    self.raise_uncaught_exception(exc)
    ~~~~~~~~~~~~~~~~~~~~~~~~~~~~~^^^^^
  File "/usr/local/lib/python3.13/site-packages/rest_framework/views.py", line 480, in raise_uncaught_exception
    raise exc
  File "/usr/local/lib/python3.13/site-packages/rest_framework/views.py", line 506, in dispatch
    response = handler(request, *args, **kwargs)
  File "/app/accounts/views.py", line 109, in get
    self.send_2fa_code(profile)
    ~~~~~~~~~~~~~~~~~~^^^^^^^^^
  File "/app/accounts/views.py", line 137, in send_2fa_code
    send_mail(
    ~~~~~~~~~^
        'Your 2FA Code',
        ^^^^^^^^^^^^^^^^
    ...<3 lines>...
        fail_silently=False,
        ^^^^^^^^^^^^^^^^^^^^
    )
    ^
  File "/usr/local/lib/python3.13/site-packages/django/core/mail/__init__.py", line 88, in send_mail
    return mail.send()
           ~~~~~~~~~^^
  File "/usr/local/lib/python3.13/site-packages/django/core/mail/message.py", line 301, in send
    return self.get_connection(fail_silently).send_messages([self])
           ~~~~~~~~~~~~~~~~~~~~~~~~~~~~~~~~~~~~~~~~~~~~~~~~^^^^^^^^
  File "/usr/local/lib/python3.13/site-packages/django/core/mail/backends/smtp.py", line 128, in send_messages
    new_conn_created = self.open()
  File "/usr/local/lib/python3.13/site-packages/django/core/mail/backends/smtp.py", line 95, in open
    self.connection.login(self.username, self.password)
    ~~~~~~~~~~~~~~~~~~~~~^^^^^^^^^^^^^^^^^^^^^^^^^^^^^^
  File "/usr/local/lib/python3.13/smtplib.py", line 750, in login
    raise last_exception
  File "/usr/local/lib/python3.13/smtplib.py", line 739, in login
    (code, resp) = self.auth(
                   ~~~~~~~~~^
        authmethod, getattr(self, method_name),
        ^^^^^^^^^^^^^^^^^^^^^^^^^^^^^^^^^^^^^^^
        initial_response_ok=initial_response_ok)
        ^^^^^^^^^^^^^^^^^^^^^^^^^^^^^^^^^^^^^^^^
  File "/usr/local/lib/python3.13/smtplib.py", line 662, in auth
    raise SMTPAuthenticationError(code, resp)
smtplib.SMTPAuthenticationError: (535, b'5.7.8 Username and Password not accepted. For more information, go to\n5.7.8  https://support.google.com/mail/?p=BadCredentials 5b1f17b1804b1-43890461fc6sm77777385e9.29 - gsmtp')
2025-01-18 18:28:54,982 - DEBUG - Starting new HTTPS connection (1): api.intra.42.fr:443
2025-01-18 18:28:55,198 - DEBUG - https://api.intra.42.fr:443 "POST /oauth/token HTTP/1.1" 401 None
2025-01-18 18:28:55,216 - WARNING - Bad Request: /accounts/callback/
2025-01-18 18:29:07,197 - WARNING - No refresh token provided.
2025-01-18 18:29:07,197 - WARNING - Unauthorized: /accounts/test/
2025-01-18 18:29:07,448 - DEBUG - Starting new HTTPS connection (1): api.intra.42.fr:443
2025-01-18 18:29:07,705 - DEBUG - https://api.intra.42.fr:443 "POST /oauth/token HTTP/1.1" 200 None
2025-01-18 18:29:07,706 - DEBUG - Starting new HTTPS connection (1): api.intra.42.fr:443
2025-01-18 18:29:08,281 - DEBUG - https://api.intra.42.fr:443 "GET /v2/me HTTP/1.1" 200 None
2025-01-18 18:29:09,318 - ERROR - Internal Server Error: /accounts/callback/
Traceback (most recent call last):
  File "/usr/local/lib/python3.13/site-packages/django/core/handlers/exception.py", line 55, in inner
    response = get_response(request)
  File "/usr/local/lib/python3.13/site-packages/django/core/handlers/base.py", line 197, in _get_response
    response = wrapped_callback(request, *callback_args, **callback_kwargs)
  File "/usr/local/lib/python3.13/site-packages/django/views/decorators/csrf.py", line 65, in _view_wrapper
    return view_func(request, *args, **kwargs)
  File "/usr/local/lib/python3.13/site-packages/django/views/generic/base.py", line 104, in view
    return self.dispatch(request, *args, **kwargs)
           ~~~~~~~~~~~~~^^^^^^^^^^^^^^^^^^^^^^^^^^
  File "/usr/local/lib/python3.13/site-packages/rest_framework/views.py", line 509, in dispatch
    response = self.handle_exception(exc)
  File "/usr/local/lib/python3.13/site-packages/rest_framework/views.py", line 469, in handle_exception
    self.raise_uncaught_exception(exc)
    ~~~~~~~~~~~~~~~~~~~~~~~~~~~~~^^^^^
  File "/usr/local/lib/python3.13/site-packages/rest_framework/views.py", line 480, in raise_uncaught_exception
    raise exc
  File "/usr/local/lib/python3.13/site-packages/rest_framework/views.py", line 506, in dispatch
    response = handler(request, *args, **kwargs)
  File "/app/accounts/views.py", line 109, in get
    self.send_2fa_code(profile)
    ~~~~~~~~~~~~~~~~~~^^^^^^^^^
  File "/app/accounts/views.py", line 137, in send_2fa_code
    send_mail(
    ~~~~~~~~~^
        'Your 2FA Code',
        ^^^^^^^^^^^^^^^^
    ...<3 lines>...
        fail_silently=False,
        ^^^^^^^^^^^^^^^^^^^^
    )
    ^
  File "/usr/local/lib/python3.13/site-packages/django/core/mail/__init__.py", line 88, in send_mail
    return mail.send()
           ~~~~~~~~~^^
  File "/usr/local/lib/python3.13/site-packages/django/core/mail/message.py", line 301, in send
    return self.get_connection(fail_silently).send_messages([self])
           ~~~~~~~~~~~~~~~~~~~~~~~~~~~~~~~~~~~~~~~~~~~~~~~~^^^^^^^^
  File "/usr/local/lib/python3.13/site-packages/django/core/mail/backends/smtp.py", line 128, in send_messages
    new_conn_created = self.open()
  File "/usr/local/lib/python3.13/site-packages/django/core/mail/backends/smtp.py", line 95, in open
    self.connection.login(self.username, self.password)
    ~~~~~~~~~~~~~~~~~~~~~^^^^^^^^^^^^^^^^^^^^^^^^^^^^^^
  File "/usr/local/lib/python3.13/smtplib.py", line 750, in login
    raise last_exception
  File "/usr/local/lib/python3.13/smtplib.py", line 739, in login
    (code, resp) = self.auth(
                   ~~~~~~~~~^
        authmethod, getattr(self, method_name),
        ^^^^^^^^^^^^^^^^^^^^^^^^^^^^^^^^^^^^^^^
        initial_response_ok=initial_response_ok)
        ^^^^^^^^^^^^^^^^^^^^^^^^^^^^^^^^^^^^^^^^
  File "/usr/local/lib/python3.13/smtplib.py", line 662, in auth
    raise SMTPAuthenticationError(code, resp)
smtplib.SMTPAuthenticationError: (535, b'5.7.8 Username and Password not accepted. For more information, go to\n5.7.8  https://support.google.com/mail/?p=BadCredentials ffacd0b85a97d-38bf32154b5sm5839198f8f.16 - gsmtp')
2025-01-18 18:42:39,631 - DEBUG - Starting new HTTPS connection (1): api.intra.42.fr:443
2025-01-18 18:42:39,879 - DEBUG - https://api.intra.42.fr:443 "POST /oauth/token HTTP/1.1" 401 None
2025-01-18 18:42:39,882 - WARNING - Bad Request: /accounts/callback/
2025-01-18 18:42:46,158 - WARNING - No refresh token provided.
2025-01-18 18:42:46,159 - WARNING - Unauthorized: /accounts/test/
2025-01-18 18:42:46,458 - DEBUG - Starting new HTTPS connection (1): api.intra.42.fr:443
2025-01-18 18:42:46,716 - DEBUG - https://api.intra.42.fr:443 "POST /oauth/token HTTP/1.1" 200 None
2025-01-18 18:42:46,717 - DEBUG - Starting new HTTPS connection (1): api.intra.42.fr:443
2025-01-18 18:42:47,255 - DEBUG - https://api.intra.42.fr:443 "GET /v2/me HTTP/1.1" 200 None
2025-01-18 18:42:48,293 - ERROR - Internal Server Error: /accounts/callback/
Traceback (most recent call last):
  File "/usr/local/lib/python3.13/site-packages/django/core/handlers/exception.py", line 55, in inner
    response = get_response(request)
  File "/usr/local/lib/python3.13/site-packages/django/core/handlers/base.py", line 197, in _get_response
    response = wrapped_callback(request, *callback_args, **callback_kwargs)
  File "/usr/local/lib/python3.13/site-packages/django/views/decorators/csrf.py", line 65, in _view_wrapper
    return view_func(request, *args, **kwargs)
  File "/usr/local/lib/python3.13/site-packages/django/views/generic/base.py", line 104, in view
    return self.dispatch(request, *args, **kwargs)
           ~~~~~~~~~~~~~^^^^^^^^^^^^^^^^^^^^^^^^^^
  File "/usr/local/lib/python3.13/site-packages/rest_framework/views.py", line 509, in dispatch
    response = self.handle_exception(exc)
  File "/usr/local/lib/python3.13/site-packages/rest_framework/views.py", line 469, in handle_exception
    self.raise_uncaught_exception(exc)
    ~~~~~~~~~~~~~~~~~~~~~~~~~~~~~^^^^^
  File "/usr/local/lib/python3.13/site-packages/rest_framework/views.py", line 480, in raise_uncaught_exception
    raise exc
  File "/usr/local/lib/python3.13/site-packages/rest_framework/views.py", line 506, in dispatch
    response = handler(request, *args, **kwargs)
  File "/app/accounts/views.py", line 109, in get
    self.send_2fa_code(profile)
    ~~~~~~~~~~~~~~~~~~^^^^^^^^^
  File "/app/accounts/views.py", line 137, in send_2fa_code
    send_mail(
    ~~~~~~~~~^
        'Your 2FA Code',
        ^^^^^^^^^^^^^^^^
    ...<3 lines>...
        fail_silently=False,
        ^^^^^^^^^^^^^^^^^^^^
    )
    ^
  File "/usr/local/lib/python3.13/site-packages/django/core/mail/__init__.py", line 88, in send_mail
    return mail.send()
           ~~~~~~~~~^^
  File "/usr/local/lib/python3.13/site-packages/django/core/mail/message.py", line 301, in send
    return self.get_connection(fail_silently).send_messages([self])
           ~~~~~~~~~~~~~~~~~~~~~~~~~~~~~~~~~~~~~~~~~~~~~~~~^^^^^^^^
  File "/usr/local/lib/python3.13/site-packages/django/core/mail/backends/smtp.py", line 128, in send_messages
    new_conn_created = self.open()
  File "/usr/local/lib/python3.13/site-packages/django/core/mail/backends/smtp.py", line 95, in open
    self.connection.login(self.username, self.password)
    ~~~~~~~~~~~~~~~~~~~~~^^^^^^^^^^^^^^^^^^^^^^^^^^^^^^
  File "/usr/local/lib/python3.13/smtplib.py", line 750, in login
    raise last_exception
  File "/usr/local/lib/python3.13/smtplib.py", line 739, in login
    (code, resp) = self.auth(
                   ~~~~~~~~~^
        authmethod, getattr(self, method_name),
        ^^^^^^^^^^^^^^^^^^^^^^^^^^^^^^^^^^^^^^^
        initial_response_ok=initial_response_ok)
        ^^^^^^^^^^^^^^^^^^^^^^^^^^^^^^^^^^^^^^^^
  File "/usr/local/lib/python3.13/smtplib.py", line 662, in auth
    raise SMTPAuthenticationError(code, resp)
smtplib.SMTPAuthenticationError: (534, b'5.7.9 Application-specific password required. For more information, go to\n5.7.9  https://support.google.com/mail/?p=InvalidSecondFactor 5b1f17b1804b1-4389046bab0sm75205735e9.38 - gsmtp')
2025-01-18 18:43:13,137 - DEBUG - Starting new HTTPS connection (1): api.intra.42.fr:443
2025-01-18 18:43:13,247 - DEBUG - https://api.intra.42.fr:443 "POST /oauth/token HTTP/1.1" 401 None
2025-01-18 18:43:13,267 - WARNING - Bad Request: /accounts/callback/
2025-01-18 18:43:17,562 - WARNING - No refresh token provided.
2025-01-18 18:43:17,563 - WARNING - Unauthorized: /accounts/test/
2025-01-18 18:43:17,820 - DEBUG - Starting new HTTPS connection (1): api.intra.42.fr:443
2025-01-18 18:43:18,069 - DEBUG - https://api.intra.42.fr:443 "POST /oauth/token HTTP/1.1" 200 None
2025-01-18 18:43:18,070 - DEBUG - Starting new HTTPS connection (1): api.intra.42.fr:443
2025-01-18 18:43:18,576 - DEBUG - https://api.intra.42.fr:443 "GET /v2/me HTTP/1.1" 200 None
2025-01-18 18:43:19,604 - ERROR - Internal Server Error: /accounts/callback/
Traceback (most recent call last):
  File "/usr/local/lib/python3.13/site-packages/django/core/handlers/exception.py", line 55, in inner
    response = get_response(request)
  File "/usr/local/lib/python3.13/site-packages/django/core/handlers/base.py", line 197, in _get_response
    response = wrapped_callback(request, *callback_args, **callback_kwargs)
  File "/usr/local/lib/python3.13/site-packages/django/views/decorators/csrf.py", line 65, in _view_wrapper
    return view_func(request, *args, **kwargs)
  File "/usr/local/lib/python3.13/site-packages/django/views/generic/base.py", line 104, in view
    return self.dispatch(request, *args, **kwargs)
           ~~~~~~~~~~~~~^^^^^^^^^^^^^^^^^^^^^^^^^^
  File "/usr/local/lib/python3.13/site-packages/rest_framework/views.py", line 509, in dispatch
    response = self.handle_exception(exc)
  File "/usr/local/lib/python3.13/site-packages/rest_framework/views.py", line 469, in handle_exception
    self.raise_uncaught_exception(exc)
    ~~~~~~~~~~~~~~~~~~~~~~~~~~~~~^^^^^
  File "/usr/local/lib/python3.13/site-packages/rest_framework/views.py", line 480, in raise_uncaught_exception
    raise exc
  File "/usr/local/lib/python3.13/site-packages/rest_framework/views.py", line 506, in dispatch
    response = handler(request, *args, **kwargs)
  File "/app/accounts/views.py", line 109, in get
    self.send_2fa_code(profile)
    ~~~~~~~~~~~~~~~~~~^^^^^^^^^
  File "/app/accounts/views.py", line 137, in send_2fa_code
    send_mail(
    ~~~~~~~~~^
        'Your 2FA Code',
        ^^^^^^^^^^^^^^^^
    ...<3 lines>...
        fail_silently=False,
        ^^^^^^^^^^^^^^^^^^^^
    )
    ^
  File "/usr/local/lib/python3.13/site-packages/django/core/mail/__init__.py", line 88, in send_mail
    return mail.send()
           ~~~~~~~~~^^
  File "/usr/local/lib/python3.13/site-packages/django/core/mail/message.py", line 301, in send
    return self.get_connection(fail_silently).send_messages([self])
           ~~~~~~~~~~~~~~~~~~~~~~~~~~~~~~~~~~~~~~~~~~~~~~~~^^^^^^^^
  File "/usr/local/lib/python3.13/site-packages/django/core/mail/backends/smtp.py", line 128, in send_messages
    new_conn_created = self.open()
  File "/usr/local/lib/python3.13/site-packages/django/core/mail/backends/smtp.py", line 95, in open
    self.connection.login(self.username, self.password)
    ~~~~~~~~~~~~~~~~~~~~~^^^^^^^^^^^^^^^^^^^^^^^^^^^^^^
  File "/usr/local/lib/python3.13/smtplib.py", line 750, in login
    raise last_exception
  File "/usr/local/lib/python3.13/smtplib.py", line 739, in login
    (code, resp) = self.auth(
                   ~~~~~~~~~^
        authmethod, getattr(self, method_name),
        ^^^^^^^^^^^^^^^^^^^^^^^^^^^^^^^^^^^^^^^
        initial_response_ok=initial_response_ok)
        ^^^^^^^^^^^^^^^^^^^^^^^^^^^^^^^^^^^^^^^^
  File "/usr/local/lib/python3.13/smtplib.py", line 662, in auth
    raise SMTPAuthenticationError(code, resp)
smtplib.SMTPAuthenticationError: (534, b'5.7.9 Application-specific password required. For more information, go to\n5.7.9  https://support.google.com/mail/?p=InvalidSecondFactor 5b1f17b1804b1-4389041f603sm76295075e9.21 - gsmtp')
2025-01-18 18:51:55,570 - DEBUG - Starting new HTTPS connection (1): api.intra.42.fr:443
2025-01-18 18:51:55,870 - DEBUG - https://api.intra.42.fr:443 "POST /oauth/token HTTP/1.1" 401 None
2025-01-18 18:51:55,885 - WARNING - Bad Request: /accounts/callback/
2025-01-18 18:51:58,576 - WARNING - No refresh token provided.
2025-01-18 18:51:58,576 - WARNING - Unauthorized: /accounts/test/
2025-01-18 18:51:58,882 - DEBUG - Starting new HTTPS connection (1): api.intra.42.fr:443
2025-01-18 18:51:59,025 - DEBUG - https://api.intra.42.fr:443 "POST /oauth/token HTTP/1.1" 200 None
2025-01-18 18:51:59,026 - DEBUG - Starting new HTTPS connection (1): api.intra.42.fr:443
2025-01-18 18:51:59,577 - DEBUG - https://api.intra.42.fr:443 "GET /v2/me HTTP/1.1" 200 None
2025-01-18 18:52:00,616 - ERROR - Internal Server Error: /accounts/callback/
Traceback (most recent call last):
  File "/usr/local/lib/python3.13/site-packages/django/core/handlers/exception.py", line 55, in inner
    response = get_response(request)
  File "/usr/local/lib/python3.13/site-packages/django/core/handlers/base.py", line 197, in _get_response
    response = wrapped_callback(request, *callback_args, **callback_kwargs)
  File "/usr/local/lib/python3.13/site-packages/django/views/decorators/csrf.py", line 65, in _view_wrapper
    return view_func(request, *args, **kwargs)
  File "/usr/local/lib/python3.13/site-packages/django/views/generic/base.py", line 104, in view
    return self.dispatch(request, *args, **kwargs)
           ~~~~~~~~~~~~~^^^^^^^^^^^^^^^^^^^^^^^^^^
  File "/usr/local/lib/python3.13/site-packages/rest_framework/views.py", line 509, in dispatch
    response = self.handle_exception(exc)
  File "/usr/local/lib/python3.13/site-packages/rest_framework/views.py", line 469, in handle_exception
    self.raise_uncaught_exception(exc)
    ~~~~~~~~~~~~~~~~~~~~~~~~~~~~~^^^^^
  File "/usr/local/lib/python3.13/site-packages/rest_framework/views.py", line 480, in raise_uncaught_exception
    raise exc
  File "/usr/local/lib/python3.13/site-packages/rest_framework/views.py", line 506, in dispatch
    response = handler(request, *args, **kwargs)
  File "/app/accounts/views.py", line 109, in get
    self.send_2fa_code(profile)
    ~~~~~~~~~~~~~~~~~~^^^^^^^^^
  File "/app/accounts/views.py", line 137, in send_2fa_code
    send_mail(
    ~~~~~~~~~^
        'Your 2FA Code',
        ^^^^^^^^^^^^^^^^
    ...<3 lines>...
        fail_silently=False,
        ^^^^^^^^^^^^^^^^^^^^
    )
    ^
  File "/usr/local/lib/python3.13/site-packages/django/core/mail/__init__.py", line 88, in send_mail
    return mail.send()
           ~~~~~~~~~^^
  File "/usr/local/lib/python3.13/site-packages/django/core/mail/message.py", line 301, in send
    return self.get_connection(fail_silently).send_messages([self])
           ~~~~~~~~~~~~~~~~~~~~~~~~~~~~~~~~~~~~~~~~~~~~~~~~^^^^^^^^
  File "/usr/local/lib/python3.13/site-packages/django/core/mail/backends/smtp.py", line 128, in send_messages
    new_conn_created = self.open()
  File "/usr/local/lib/python3.13/site-packages/django/core/mail/backends/smtp.py", line 95, in open
    self.connection.login(self.username, self.password)
    ~~~~~~~~~~~~~~~~~~~~~^^^^^^^^^^^^^^^^^^^^^^^^^^^^^^
  File "/usr/local/lib/python3.13/smtplib.py", line 750, in login
    raise last_exception
  File "/usr/local/lib/python3.13/smtplib.py", line 739, in login
    (code, resp) = self.auth(
                   ~~~~~~~~~^
        authmethod, getattr(self, method_name),
        ^^^^^^^^^^^^^^^^^^^^^^^^^^^^^^^^^^^^^^^
        initial_response_ok=initial_response_ok)
        ^^^^^^^^^^^^^^^^^^^^^^^^^^^^^^^^^^^^^^^^
  File "/usr/local/lib/python3.13/smtplib.py", line 662, in auth
    raise SMTPAuthenticationError(code, resp)
smtplib.SMTPAuthenticationError: (535, b'5.7.8 Username and Password not accepted. For more information, go to\n5.7.8  https://support.google.com/mail/?p=BadCredentials ffacd0b85a97d-38bf321537dsm5937825f8f.13 - gsmtp')
2025-01-18 18:54:22,211 - DEBUG - Starting new HTTPS connection (1): api.intra.42.fr:443
2025-01-18 18:54:22,322 - DEBUG - https://api.intra.42.fr:443 "POST /oauth/token HTTP/1.1" 401 None
2025-01-18 18:54:22,335 - WARNING - Bad Request: /accounts/callback/
2025-01-18 18:54:31,343 - WARNING - No refresh token provided.
2025-01-18 18:54:31,343 - WARNING - Unauthorized: /accounts/test/
2025-01-18 18:54:31,690 - DEBUG - Starting new HTTPS connection (1): api.intra.42.fr:443
2025-01-18 18:54:31,831 - DEBUG - https://api.intra.42.fr:443 "POST /oauth/token HTTP/1.1" 200 None
2025-01-18 18:54:31,835 - DEBUG - Starting new HTTPS connection (1): api.intra.42.fr:443
2025-01-18 18:54:32,384 - DEBUG - https://api.intra.42.fr:443 "GET /v2/me HTTP/1.1" 200 None
2025-01-18 18:54:33,388 - ERROR - Internal Server Error: /accounts/callback/
Traceback (most recent call last):
  File "/usr/local/lib/python3.13/site-packages/django/core/handlers/exception.py", line 55, in inner
    response = get_response(request)
  File "/usr/local/lib/python3.13/site-packages/django/core/handlers/base.py", line 197, in _get_response
    response = wrapped_callback(request, *callback_args, **callback_kwargs)
  File "/usr/local/lib/python3.13/site-packages/django/views/decorators/csrf.py", line 65, in _view_wrapper
    return view_func(request, *args, **kwargs)
  File "/usr/local/lib/python3.13/site-packages/django/views/generic/base.py", line 104, in view
    return self.dispatch(request, *args, **kwargs)
           ~~~~~~~~~~~~~^^^^^^^^^^^^^^^^^^^^^^^^^^
  File "/usr/local/lib/python3.13/site-packages/rest_framework/views.py", line 509, in dispatch
    response = self.handle_exception(exc)
  File "/usr/local/lib/python3.13/site-packages/rest_framework/views.py", line 469, in handle_exception
    self.raise_uncaught_exception(exc)
    ~~~~~~~~~~~~~~~~~~~~~~~~~~~~~^^^^^
  File "/usr/local/lib/python3.13/site-packages/rest_framework/views.py", line 480, in raise_uncaught_exception
    raise exc
  File "/usr/local/lib/python3.13/site-packages/rest_framework/views.py", line 506, in dispatch
    response = handler(request, *args, **kwargs)
  File "/app/accounts/views.py", line 109, in get
    self.send_2fa_code(profile)
    ~~~~~~~~~~~~~~~~~~^^^^^^^^^
  File "/app/accounts/views.py", line 137, in send_2fa_code
    send_mail(
    ~~~~~~~~~^
        'Your 2FA Code',
        ^^^^^^^^^^^^^^^^
    ...<3 lines>...
        fail_silently=False,
        ^^^^^^^^^^^^^^^^^^^^
    )
    ^
  File "/usr/local/lib/python3.13/site-packages/django/core/mail/__init__.py", line 88, in send_mail
    return mail.send()
           ~~~~~~~~~^^
  File "/usr/local/lib/python3.13/site-packages/django/core/mail/message.py", line 301, in send
    return self.get_connection(fail_silently).send_messages([self])
           ~~~~~~~~~~~~~~~~~~~~~~~~~~~~~~~~~~~~~~~~~~~~~~~~^^^^^^^^
  File "/usr/local/lib/python3.13/site-packages/django/core/mail/backends/smtp.py", line 128, in send_messages
    new_conn_created = self.open()
  File "/usr/local/lib/python3.13/site-packages/django/core/mail/backends/smtp.py", line 95, in open
    self.connection.login(self.username, self.password)
    ~~~~~~~~~~~~~~~~~~~~~^^^^^^^^^^^^^^^^^^^^^^^^^^^^^^
  File "/usr/local/lib/python3.13/smtplib.py", line 750, in login
    raise last_exception
  File "/usr/local/lib/python3.13/smtplib.py", line 739, in login
    (code, resp) = self.auth(
                   ~~~~~~~~~^
        authmethod, getattr(self, method_name),
        ^^^^^^^^^^^^^^^^^^^^^^^^^^^^^^^^^^^^^^^
        initial_response_ok=initial_response_ok)
        ^^^^^^^^^^^^^^^^^^^^^^^^^^^^^^^^^^^^^^^^
  File "/usr/local/lib/python3.13/smtplib.py", line 662, in auth
    raise SMTPAuthenticationError(code, resp)
smtplib.SMTPAuthenticationError: (535, b'5.7.8 Username and Password not accepted. For more information, go to\n5.7.8  https://support.google.com/mail/?p=BadCredentials ffacd0b85a97d-38bf32154b5sm5885970f8f.16 - gsmtp')
2025-01-18 19:04:35,024 - DEBUG - Starting new HTTPS connection (1): api.intra.42.fr:443
2025-01-18 19:04:35,269 - DEBUG - https://api.intra.42.fr:443 "POST /oauth/token HTTP/1.1" 401 None
2025-01-18 19:04:35,272 - WARNING - Bad Request: /accounts/callback/
2025-01-18 19:04:39,170 - WARNING - No refresh token provided.
2025-01-18 19:04:39,171 - WARNING - Unauthorized: /accounts/test/
2025-01-18 19:04:39,469 - DEBUG - Starting new HTTPS connection (1): api.intra.42.fr:443
2025-01-18 19:04:39,714 - DEBUG - https://api.intra.42.fr:443 "POST /oauth/token HTTP/1.1" 200 None
2025-01-18 19:04:39,715 - DEBUG - Starting new HTTPS connection (1): api.intra.42.fr:443
2025-01-18 19:04:40,133 - DEBUG - https://api.intra.42.fr:443 "GET /v2/me HTTP/1.1" 200 None
2025-01-18 19:04:41,192 - ERROR - Internal Server Error: /accounts/callback/
Traceback (most recent call last):
  File "/usr/local/lib/python3.13/site-packages/django/core/handlers/exception.py", line 55, in inner
    response = get_response(request)
  File "/usr/local/lib/python3.13/site-packages/django/core/handlers/base.py", line 197, in _get_response
    response = wrapped_callback(request, *callback_args, **callback_kwargs)
  File "/usr/local/lib/python3.13/site-packages/django/views/decorators/csrf.py", line 65, in _view_wrapper
    return view_func(request, *args, **kwargs)
  File "/usr/local/lib/python3.13/site-packages/django/views/generic/base.py", line 104, in view
    return self.dispatch(request, *args, **kwargs)
           ~~~~~~~~~~~~~^^^^^^^^^^^^^^^^^^^^^^^^^^
  File "/usr/local/lib/python3.13/site-packages/rest_framework/views.py", line 509, in dispatch
    response = self.handle_exception(exc)
  File "/usr/local/lib/python3.13/site-packages/rest_framework/views.py", line 469, in handle_exception
    self.raise_uncaught_exception(exc)
    ~~~~~~~~~~~~~~~~~~~~~~~~~~~~~^^^^^
  File "/usr/local/lib/python3.13/site-packages/rest_framework/views.py", line 480, in raise_uncaught_exception
    raise exc
  File "/usr/local/lib/python3.13/site-packages/rest_framework/views.py", line 506, in dispatch
    response = handler(request, *args, **kwargs)
  File "/app/accounts/views.py", line 109, in get
    self.send_2fa_code(profile)
    ~~~~~~~~~~~~~~~~~~^^^^^^^^^
  File "/app/accounts/views.py", line 137, in send_2fa_code
    send_mail(
    ~~~~~~~~~^
        'Your 2FA Code',
        ^^^^^^^^^^^^^^^^
    ...<3 lines>...
        fail_silently=False,
        ^^^^^^^^^^^^^^^^^^^^
    )
    ^
  File "/usr/local/lib/python3.13/site-packages/django/core/mail/__init__.py", line 88, in send_mail
    return mail.send()
           ~~~~~~~~~^^
  File "/usr/local/lib/python3.13/site-packages/django/core/mail/message.py", line 301, in send
    return self.get_connection(fail_silently).send_messages([self])
           ~~~~~~~~~~~~~~~~~~~~~~~~~~~~~~~~~~~~~~~~~~~~~~~~^^^^^^^^
  File "/usr/local/lib/python3.13/site-packages/django/core/mail/backends/smtp.py", line 128, in send_messages
    new_conn_created = self.open()
  File "/usr/local/lib/python3.13/site-packages/django/core/mail/backends/smtp.py", line 95, in open
    self.connection.login(self.username, self.password)
    ~~~~~~~~~~~~~~~~~~~~~^^^^^^^^^^^^^^^^^^^^^^^^^^^^^^
  File "/usr/local/lib/python3.13/smtplib.py", line 750, in login
    raise last_exception
  File "/usr/local/lib/python3.13/smtplib.py", line 739, in login
    (code, resp) = self.auth(
                   ~~~~~~~~~^
        authmethod, getattr(self, method_name),
        ^^^^^^^^^^^^^^^^^^^^^^^^^^^^^^^^^^^^^^^
        initial_response_ok=initial_response_ok)
        ^^^^^^^^^^^^^^^^^^^^^^^^^^^^^^^^^^^^^^^^
  File "/usr/local/lib/python3.13/smtplib.py", line 662, in auth
    raise SMTPAuthenticationError(code, resp)
smtplib.SMTPAuthenticationError: (535, b'5.7.8 Username and Password not accepted. For more information, go to\n5.7.8  https://support.google.com/mail/?p=BadCredentials 5b1f17b1804b1-43890412f7csm76356215e9.9 - gsmtp')
2025-01-18 19:08:14,006 - WARNING - No refresh token provided.
2025-01-18 19:08:14,007 - WARNING - Unauthorized: /accounts/test/
2025-01-18 19:08:14,284 - DEBUG - Starting new HTTPS connection (1): api.intra.42.fr:443
2025-01-18 19:08:14,553 - DEBUG - https://api.intra.42.fr:443 "POST /oauth/token HTTP/1.1" 200 None
2025-01-18 19:08:14,555 - DEBUG - Starting new HTTPS connection (1): api.intra.42.fr:443
2025-01-18 19:08:14,990 - DEBUG - https://api.intra.42.fr:443 "GET /v2/me HTTP/1.1" 200 None
2025-01-18 19:09:12,197 - DEBUG - Starting new HTTPS connection (1): api.intra.42.fr:443
2025-01-18 19:09:12,415 - DEBUG - https://api.intra.42.fr:443 "POST /oauth/token HTTP/1.1" 401 None
2025-01-18 19:09:12,429 - WARNING - Bad Request: /accounts/callback/
2025-01-18 19:09:16,110 - DEBUG - Starting new HTTPS connection (1): api.intra.42.fr:443
2025-01-18 19:09:16,224 - DEBUG - https://api.intra.42.fr:443 "POST /oauth/token HTTP/1.1" 401 None
2025-01-18 19:09:16,228 - WARNING - Bad Request: /accounts/callback/
2025-01-18 19:09:17,569 - DEBUG - Starting new HTTPS connection (1): api.intra.42.fr:443
2025-01-18 19:09:17,780 - DEBUG - https://api.intra.42.fr:443 "POST /oauth/token HTTP/1.1" 401 None
2025-01-18 19:09:17,784 - WARNING - Bad Request: /accounts/callback/
2025-01-18 19:09:18,485 - DEBUG - Starting new HTTPS connection (1): api.intra.42.fr:443
2025-01-18 19:09:18,598 - DEBUG - https://api.intra.42.fr:443 "POST /oauth/token HTTP/1.1" 401 None
2025-01-18 19:09:18,602 - WARNING - Bad Request: /accounts/callback/
2025-01-18 19:09:19,546 - DEBUG - Starting new HTTPS connection (1): api.intra.42.fr:443
2025-01-18 19:09:19,765 - DEBUG - https://api.intra.42.fr:443 "POST /oauth/token HTTP/1.1" 401 None
2025-01-18 19:09:19,768 - WARNING - Bad Request: /accounts/callback/
2025-01-18 19:09:20,705 - DEBUG - Starting new HTTPS connection (1): api.intra.42.fr:443
2025-01-18 19:09:20,816 - DEBUG - https://api.intra.42.fr:443 "POST /oauth/token HTTP/1.1" 401 None
2025-01-18 19:09:20,820 - WARNING - Bad Request: /accounts/callback/
2025-01-18 19:09:21,642 - DEBUG - Starting new HTTPS connection (1): api.intra.42.fr:443
2025-01-18 19:09:21,855 - DEBUG - https://api.intra.42.fr:443 "POST /oauth/token HTTP/1.1" 401 None
2025-01-18 19:09:21,860 - WARNING - Bad Request: /accounts/callback/
2025-01-18 19:09:32,133 - INFO - {'detail': errordetail(string='given token not valid for any token type', code='token_not_valid'), 'code': errordetail(string='token_not_valid', code='token_not_valid'), 'messages': [{'token_class': errordetail(string='accesstoken', code='token_not_valid'), 'token_type': errordetail(string='access', code='token_not_valid'), 'message': errordetail(string='token is invalid or expired', code='token_not_valid')}]}
2025-01-18 19:09:55,146 - WARNING - No refresh token provided.
2025-01-18 19:09:55,147 - WARNING - Unauthorized: /accounts/test/
2025-01-18 19:09:55,368 - DEBUG - Starting new HTTPS connection (1): api.intra.42.fr:443
2025-01-18 19:09:55,540 - DEBUG - https://api.intra.42.fr:443 "POST /oauth/token HTTP/1.1" 200 None
2025-01-18 19:09:55,541 - DEBUG - Starting new HTTPS connection (1): api.intra.42.fr:443
2025-01-18 19:09:55,964 - DEBUG - https://api.intra.42.fr:443 "GET /v2/me HTTP/1.1" 200 None
2025-01-18 19:11:51,585 - INFO - {'detail': errordetail(string='given token not valid for any token type', code='token_not_valid'), 'code': errordetail(string='token_not_valid', code='token_not_valid'), 'messages': [{'token_class': errordetail(string='accesstoken', code='token_not_valid'), 'token_type': errordetail(string='access', code='token_not_valid'), 'message': errordetail(string='token is invalid or expired', code='token_not_valid')}]}
2025-01-18 19:12:18,935 - INFO - User edamar authenticated successfully.
2025-01-18 19:13:59,684 - INFO - {'detail': errordetail(string='given token not valid for any token type', code='token_not_valid'), 'code': errordetail(string='token_not_valid', code='token_not_valid'), 'messages': [{'token_class': errordetail(string='accesstoken', code='token_not_valid'), 'token_type': errordetail(string='access', code='token_not_valid'), 'message': errordetail(string='token is invalid or expired', code='token_not_valid')}]}
2025-01-18 19:14:03,136 - INFO - User edamar authenticated successfully.
2025-01-18 19:14:07,906 - INFO - User edamar authenticated successfully.
2025-01-18 19:14:16,711 - DEBUG - Starting new HTTPS connection (1): api.intra.42.fr:443
2025-01-18 19:14:16,962 - DEBUG - https://api.intra.42.fr:443 "POST /oauth/token HTTP/1.1" 200 None
2025-01-18 19:14:16,963 - DEBUG - Starting new HTTPS connection (1): api.intra.42.fr:443
2025-01-18 19:14:17,560 - DEBUG - https://api.intra.42.fr:443 "GET /v2/me HTTP/1.1" 200 None
2025-01-18 19:14:34,446 - INFO - User edamar authenticated successfully.
2025-01-18 19:16:19,750 - INFO - /app/accounts/views.py changed, reloading.
2025-01-18 19:16:46,790 - INFO - /app/accounts/views.py changed, reloading.
2025-01-18 19:16:48,473 - INFO - /app/accounts/views.py changed, reloading.
2025-01-18 19:16:54,257 - INFO - /app/accounts/views.py changed, reloading.
2025-01-18 19:16:56,065 - INFO - /app/accounts/views.py changed, reloading.
2025-01-18 19:17:02,821 - INFO - /app/accounts/views.py changed, reloading.
2025-01-18 19:17:17,700 - INFO - /app/accounts/auth.py changed, reloading.
